<?xml version="1.0" ?>

<robot name="kobuki" xmlns:xacro="http://ros.org/wiki/xacro">

    <link name="$(arg prefix)base_footprint"/>
    <!--
       Base link is set at the bottom of the base mould.
       This is done to be compatible with the way base link
       was configured for turtlebot 1. Refer to

       https://github.com/turtlebot/turtlebot/issues/40

       To put the base link at the more oft used wheel
       axis, set the z-distance from the base_footprint
       to 0.352.
      -->
    <joint name="base_joint" type="fixed">
      <origin xyz="0 0 0.0102" rpy="0 0 0" />
      <parent link="$(arg prefix)base_footprint"/>
      <child link="$(arg prefix)base_link" />
    </joint>
    <link name="$(arg prefix)base_link">
      <visual>
        <geometry>
          <!-- new mesh -->
          <mesh filename="package://kobuki_description/meshes/main_body.dae" />
        </geometry>
        <origin xyz="0.001 0 0.05199" rpy="0 0 0"/>
      </visual>
      <collision name="base">
        <geometry>
          <cylinder length="0.10938" radius="0.178"/>
        </geometry>
        <origin xyz="0.0 0 0.05949" rpy="0 0 0"/>
      </collision>
      <inertial>
        <!-- COM experimentally determined -->
        <origin xyz="0.01 0 0"/>
        <mass value="2.4"/> <!-- 2.4/2.6 kg for small/big battery pack -->
        <!-- Kobuki inertia tensor is approximated by a cylinder with homogeneous mass distribution
             More details http://en.wikipedia.org/wiki/List_of_moment_of_inertia_tensors
             m = 2.4 kg; h = 0.09 m; r = 0.175 m
             ixx = 1/12 * m * (3 * r^2 + h^2)
             iyy = 1/12 * m * (3 * r^2 + h^2)
             izz = 1/2 * m * r^2
          -->
        <inertia ixx="0.019995" ixy="0.0" ixz="0.0"
                 iyy="0.019995" iyz="0.0"
                 izz="0.03675" />
      </inertial>
    </link>

    <joint name="wheel_left_joint" type="continuous">
      <parent link="$(arg prefix)base_link"/>
      <child link="$(arg prefix)wheel_left_link"/>
      <origin xyz="0.00 ${0.23/2} 0.0250" rpy="${-pi/2} 0 0"/>
      <axis xyz="0 0 1"/>
    </joint>
    <link name="$(arg prefix)wheel_left_link">
      <visual>
        <geometry>
          <mesh filename="package://kobuki_description/meshes/wheel.dae"/>
        </geometry>
        <origin xyz="0 0 0" rpy="0 0 0"/>
      </visual>
      <collision>
        <geometry>
          <cylinder length="0.0206" radius="0.035"/>
        </geometry>
        <origin rpy="0 0 0" xyz="0 0 0"/>
      </collision>
      <inertial>
        <mass value="0.01" />
        <origin xyz="0 0 0" />
        <inertia ixx="0.001" ixy="0.0" ixz="0.0"
                 iyy="0.001" iyz="0.0"
                 izz="0.001" />
      </inertial>
    </link>

    <joint name="wheel_right_joint" type="continuous">
      <parent link="$(arg prefix)base_link"/>
      <child link="$(arg prefix)wheel_right_link"/>
      <origin xyz="0.00 -${0.23/2} 0.0250" rpy="${-pi/2} 0 0"/>
      <axis xyz="0 0 1"/>
    </joint>
    <link name="$(arg prefix)wheel_right_link">
      <visual>
        <geometry>
          <mesh filename="package://kobuki_description/meshes/wheel.dae"/>
        </geometry>
        <origin xyz="0 0 0" rpy="0 0 0"/>
      </visual>
      <collision>
        <geometry>
          <cylinder length="0.0206" radius="0.035"/>
        </geometry>
        <origin rpy="0 0 0" xyz="0 0 0"/>
      </collision>
      <inertial>
        <mass value="0.01" />
        <origin xyz="0 0 0" />
        <inertia ixx="0.001" ixy="0.0" ixz="0.0"
                 iyy="0.001" iyz="0.0"
                 izz="0.001" />
      </inertial>
    </link>

    <joint name="caster_front_joint" type="fixed">
      <parent link="$(arg prefix)base_link"/>
      <child link="$(arg prefix)caster_front_link"/>
      <origin xyz="0.115 0.0 0.007" rpy="${-pi/2} 0 0"/>
    </joint>
    <link name="$(arg prefix)caster_front_link">
      <collision>
        <geometry>
          <cylinder length="0.0176" radius="0.017"/>
        </geometry>
        <origin rpy="0 0 0" xyz="0 0 0"/>
      </collision>
      <inertial>
        <mass value="0.01" />
        <origin xyz="0 0 0" />
        <inertia ixx="0.001" ixy="0.0" ixz="0.0"
                 iyy="0.001" iyz="0.0"
                 izz="0.001" />
      </inertial>
    </link>

    <joint name="caster_back_joint" type="fixed">
      <parent link="$(arg prefix)base_link"/>
      <child link="$(arg prefix)caster_back_link"/>
      <origin xyz="-0.135 0.0 0.009" rpy="${-pi/2} 0 0"/>
    </joint>
    <link name="$(arg prefix)caster_back_link">
      <collision>
        <geometry>
          <cylinder length="0.0176" radius="0.017"/>
        </geometry>
        <origin rpy="0 0 0" xyz="0 0 0"/>
      </collision>
      <inertial>
        <mass value="0.01" />
        <origin xyz="0 0 0" />
        <inertia ixx="0.001" ixy="0.0" ixz="0.0"
                 iyy="0.001" iyz="0.0"
                 izz="0.001" />
      </inertial>
    </link>

    <!-- sensors -->
    <joint name="gyro_joint" type="fixed">
      <axis xyz="0 1 0"/>
      <origin xyz="0.056 0.062 0.0202" rpy="0 0 0"/>
      <parent link="$(arg prefix)base_link"/>
      <child link="$(arg prefix)gyro_link"/>
    </joint>
    <link name="$(arg prefix)gyro_link">
      <inertial>
        <mass value="0.001"/>
        <origin xyz="0 0 0" rpy="0 0 0"/>
        <inertia ixx="0.0001" ixy="0" ixz="0"
                 iyy="0.000001" iyz="0"
                 izz="0.0001"/>
      </inertial>
    </link>

    <joint name="cliff_sensor_left_joint" type="fixed">
      <origin xyz="0.08734 0.13601 0.0214" rpy="0 ${pi/2} 0" />
      <parent link="$(arg prefix)base_link"/>
      <child link="$(arg prefix)cliff_sensor_left_link" />
    </joint>
    <link name="$(arg prefix)cliff_sensor_left_link">
      <inertial>
        <mass value="0.0001" />
        <origin xyz="0 0 0" />
        <inertia ixx="0.0001" ixy="0.0" ixz="0.0"
                 iyy="0.0001" iyz="0.0"
                 izz="0.0001" />
      </inertial>
    </link>

    <joint name="cliff_sensor_right_joint" type="fixed">
      <origin xyz="0.085 -0.13601 0.0214" rpy="0 ${pi/2} 0" />
      <parent link="$(arg prefix)base_link"/>
      <child link="$(arg prefix)cliff_sensor_right_link" />
    </joint>
    <link name="$(arg prefix)cliff_sensor_right_link">
      <inertial>
        <mass value="0.0001" />
        <origin xyz="0 0 0" />
        <inertia ixx="0.0001" ixy="0.0" ixz="0.0"
                 iyy="0.0001" iyz="0.0"
                 izz="0.0001" />
      </inertial>
    </link>

    <joint name="cliff_sensor_front_joint" type="fixed">
      <origin xyz="0.156 0.00 0.0214" rpy="0 ${pi/2} 0" />
      <parent link="$(arg prefix)base_link"/>
      <child link="$(arg prefix)cliff_sensor_front_link" />
    </joint>
    <link name="$(arg prefix)cliff_sensor_front_link">
      <inertial>
        <mass value="0.0001" />
        <origin xyz="0 0 0" />
        <inertia ixx="0.0001" ixy="0.0" ixz="0.0"
                 iyy="0.0001" iyz="0.0"
                 izz="0.0001" />
      </inertial>
    </link>

<xacro:if value="$(arg gazebo)">
<gazebo reference="$(arg prefix)wheel_left_link">
  <mu1>0.1</mu1>
  <mu2>0.1</mu2>
  <kp>500000.0</kp>
  <kd>10.0</kd>
  <minDepth>0.001</minDepth>
  <maxVel>0.1</maxVel>
  <fdir1>1 0 0</fdir1>
  <material>Gazebo/FlatBlack</material>
</gazebo>

<gazebo reference="$(arg prefix)wheel_right_link">
  <mu1>0.1</mu1>
  <mu2>0.1</mu2>
  <kp>500000.0</kp>
  <kd>10.0</kd>
  <minDepth>0.001</minDepth>
  <maxVel>0.1</maxVel>
  <fdir1>1 0 0</fdir1>
  <material>Gazebo/FlatBlack</material>
</gazebo>

<gazebo reference="$(arg prefix)caster_back_right_link">
  <mu1>0.1</mu1>
  <mu2>0.1</mu2>
  <kp>1000000.0</kp>
  <kd>100.0</kd>
  <minDepth>0.001</minDepth>
  <maxVel>1.0</maxVel>
  <material>Gazebo/FlatBlack</material>
</gazebo>

<gazebo reference="$(arg prefix)caster_back_left_link">
  <mu1>0.1</mu1>
  <mu2>0.1</mu2>
  <kp>1000000.0</kp>
  <kd>100.0</kd>
  <minDepth>0.001</minDepth>
  <maxVel>1.0</maxVel>
  <material>Gazebo/FlatBlack</material>
</gazebo>

  <gazebo reference="$(arg prefix)gyro_link">
    <sensor name="tb2_imu" type="imu">
        <always_on>true</always_on>
        <update_rate>50</update_rate>
        <topic>$(arg prefix)imu</topic>
        <gz_frame_id>$(arg prefix)gyro_link</gz_frame_id>
        <imu>
          <angular_velocity>
            <x>
              <noise type="gaussian">
                <mean>0.0</mean>
                <stddev>2e-4</stddev>
              </noise>
            </x>
            <y>
              <noise type="gaussian">
                <mean>0.0</mean>
                <stddev>2e-4</stddev>
              </noise>
            </y>
            <z>
              <noise type="gaussian">
                <mean>0.0</mean>
                <stddev>2e-4</stddev>
              </noise>
            </z>
          </angular_velocity>
          <linear_acceleration>
            <x>
              <noise type="gaussian">
                <mean>0.0</mean>
                <stddev>1.7e-2</stddev>
              </noise>
            </x>
            <y>
              <noise type="gaussian">
                <mean>0.0</mean>
                <stddev>1.7e-2</stddev>
              </noise>
            </y>
            <z>
              <noise type="gaussian">
                <mean>0.0</mean>
                <stddev>1.7e-2</stddev>
              </noise>
            </z>
          </linear_acceleration>
        </imu>
    </sensor>
    <material>Gazebo/Grey</material>
  </gazebo>

 <gazebo>
    <plugin
      filename="libignition-gazebo-diff-drive-system.so"
      name="ignition::gazebo::systems::DiffDrive">
      <left_joint>wheel_left_joint</left_joint>
      <right_joint>wheel_right_joint</right_joint>
      <wheel_separation>0.230</wheel_separation>
      <wheel_radius>0.035</wheel_radius>
      <child_frame_id>$(arg prefix)base_footprint</child_frame_id>
      <max_wheel_torque>1.0</max_wheel_torque>
      <max_wheel_acceleration>1.0</max_wheel_acceleration>
    </plugin>

    <plugin filename="libignition-gazebo-joint-state-publisher-system.so" name="ignition::gazebo::systems::JointStatePublisher"/>
      <plugin
            filename="ignition-gazebo-pose-publisher-system"
            name="ignition::gazebo::systems::PosePublisher">
            <publish_link_pose>false</publish_link_pose>
            <publish_collision_pose>false</publish_collision_pose>
            <publish_visual_pose>false</publish_visual_pose>
            <publish_nested_model_pose>true</publish_nested_model_pose>
        </plugin>

</gazebo>
</xacro:if>



</robot>
